2018-05-07 16:59:51,472 INFO: Microblog startup [in /Users/vanyroca/Desktop/BrunoCompSci/app/__init__.py:51]
2018-05-07 17:06:45,279 ERROR: Exception on /unfollow/Bruno [GET] [in /Library/Python/2.7/site-packages/flask/app.py:1560]
Traceback (most recent call last):
  File "/Library/Python/2.7/site-packages/flask/app.py", line 1982, in wsgi_app
    response = self.full_dispatch_request()
  File "/Library/Python/2.7/site-packages/flask/app.py", line 1614, in full_dispatch_request
    rv = self.handle_user_exception(e)
  File "/Library/Python/2.7/site-packages/flask/app.py", line 1517, in handle_user_exception
    reraise(exc_type, exc_value, tb)
  File "/Library/Python/2.7/site-packages/flask/app.py", line 1612, in full_dispatch_request
    rv = self.dispatch_request()
  File "/Library/Python/2.7/site-packages/flask/app.py", line 1598, in dispatch_request
    return self.view_functions[rule.endpoint](**req.view_args)
  File "/Library/Python/2.7/site-packages/flask_login/utils.py", line 261, in decorated_view
    return func(*args, **kwargs)
  File "/Users/vanyroca/Desktop/BrunoCompSci/app/routes.py", line 131, in unfollow
    user = User.qurey.filter_by(username=username).first()
AttributeError: type object 'User' has no attribute 'qurey'
2018-05-07 18:32:15,480 INFO: Microblog startup [in /Users/vanyroca/Desktop/BrunoCompSci/app/__init__.py:52]
2018-05-07 18:32:17,290 ERROR: Exception on /login [GET] [in /Library/Python/2.7/site-packages/flask/app.py:1560]
Traceback (most recent call last):
  File "/Library/Python/2.7/site-packages/flask/app.py", line 1982, in wsgi_app
    response = self.full_dispatch_request()
  File "/Library/Python/2.7/site-packages/flask/app.py", line 1614, in full_dispatch_request
    rv = self.handle_user_exception(e)
  File "/Library/Python/2.7/site-packages/flask/app.py", line 1517, in handle_user_exception
    reraise(exc_type, exc_value, tb)
  File "/Library/Python/2.7/site-packages/flask/app.py", line 1610, in full_dispatch_request
    rv = self.preprocess_request()
  File "/Library/Python/2.7/site-packages/flask/app.py", line 1831, in preprocess_request
    rv = func()
  File "/Users/vanyroca/Desktop/BrunoCompSci/app/routes.py", line 95, in before_request
    g.locale = str(get_locale())
NameError: global name 'g' is not defined
2018-05-07 18:33:11,970 INFO: Microblog startup [in /Users/vanyroca/Desktop/BrunoCompSci/app/__init__.py:52]
2018-05-07 18:33:13,482 ERROR: Exception on /login [GET] [in /Library/Python/2.7/site-packages/flask/app.py:1560]
Traceback (most recent call last):
  File "/Library/Python/2.7/site-packages/flask/app.py", line 1982, in wsgi_app
    response = self.full_dispatch_request()
  File "/Library/Python/2.7/site-packages/flask/app.py", line 1614, in full_dispatch_request
    rv = self.handle_user_exception(e)
  File "/Library/Python/2.7/site-packages/flask/app.py", line 1517, in handle_user_exception
    reraise(exc_type, exc_value, tb)
  File "/Library/Python/2.7/site-packages/flask/app.py", line 1610, in full_dispatch_request
    rv = self.preprocess_request()
  File "/Library/Python/2.7/site-packages/flask/app.py", line 1831, in preprocess_request
    rv = func()
  File "/Users/vanyroca/Desktop/BrunoCompSci/app/routes.py", line 95, in before_request
    g.locale = str(get_locale())
NameError: global name 'g' is not defined
2018-05-07 18:33:19,847 ERROR: Exception on / [GET] [in /Library/Python/2.7/site-packages/flask/app.py:1560]
Traceback (most recent call last):
  File "/Library/Python/2.7/site-packages/flask/app.py", line 1982, in wsgi_app
    response = self.full_dispatch_request()
  File "/Library/Python/2.7/site-packages/flask/app.py", line 1614, in full_dispatch_request
    rv = self.handle_user_exception(e)
  File "/Library/Python/2.7/site-packages/flask/app.py", line 1517, in handle_user_exception
    reraise(exc_type, exc_value, tb)
  File "/Library/Python/2.7/site-packages/flask/app.py", line 1610, in full_dispatch_request
    rv = self.preprocess_request()
  File "/Library/Python/2.7/site-packages/flask/app.py", line 1831, in preprocess_request
    rv = func()
  File "/Users/vanyroca/Desktop/BrunoCompSci/app/routes.py", line 95, in before_request
    g.locale = str(get_locale())
NameError: global name 'g' is not defined
2018-05-07 18:34:55,219 ERROR: Exception on /index [GET] [in /Library/Python/2.7/site-packages/flask/app.py:1560]
Traceback (most recent call last):
  File "/Library/Python/2.7/site-packages/flask/app.py", line 1982, in wsgi_app
    response = self.full_dispatch_request()
  File "/Library/Python/2.7/site-packages/flask/app.py", line 1614, in full_dispatch_request
    rv = self.handle_user_exception(e)
  File "/Library/Python/2.7/site-packages/flask/app.py", line 1517, in handle_user_exception
    reraise(exc_type, exc_value, tb)
  File "/Library/Python/2.7/site-packages/flask/app.py", line 1610, in full_dispatch_request
    rv = self.preprocess_request()
  File "/Library/Python/2.7/site-packages/flask/app.py", line 1831, in preprocess_request
    rv = func()
  File "/Users/vanyroca/Desktop/BrunoCompSci/app/routes.py", line 95, in before_request
    g.locale = str(get_locale())
NameError: global name 'g' is not defined
2018-05-07 18:35:12,649 INFO: Microblog startup [in /Users/vanyroca/Desktop/BrunoCompSci/app/__init__.py:52]
2018-05-08 16:10:50,079 INFO: Microblog startup [in /Users/vanyroca/Desktop/BrunoCompSci/app/__init__.py:52]
2018-05-11 00:58:27,597 INFO: Microblog startup [in /Users/vanyroca/Desktop/BrunoCompSci/app/__init__.py:52]
2018-05-11 01:06:51,649 INFO: Microblog startup [in /Users/vanyroca/Desktop/BrunoCompSci/app/__init__.py:52]
2018-05-11 01:07:05,537 INFO: Microblog startup [in /Users/vanyroca/Desktop/BrunoCompSci/app/__init__.py:52]
2018-05-28 00:31:27,352 INFO: Microblog startup [in /home/bberastain/Desktop/microblog/app/__init__.py:52]
2018-05-28 00:33:03,539 INFO: Microblog startup [in /home/bberastain/Desktop/microblog/app/__init__.py:52]
2018-05-28 01:12:18,211 INFO: Microblog startup [in /home/bberastain/Desktop/microblog/app/__init__.py:52]
2018-05-28 01:12:21,263 INFO: Microblog startup [in /home/bberastain/Desktop/microblog/app/__init__.py:52]
2018-05-31 14:19:43,552 INFO: Microblog startup [in /home/bberastain/Desktop/microblog/app/__init__.py:52]
